2025-05-19 23:43:57,712 - asyncio - DEBUG - Using proactor: IocpProactor
2025-05-19 23:43:57,713 - __main__ - INFO - Starting bot...
2025-05-19 23:43:57,714 - __main__ - INFO - Bot token found: 81904...
2025-05-19 23:43:57,715 - httpx - DEBUG - load_ssl_context verify=True cert=None trust_env=True http2=False
2025-05-19 23:43:57,718 - httpx - DEBUG - load_verify_locations cafile='C:\\Users\\CensoredBear.Natalia\\AppData\\Local\\Programs\\Python\\Python311\\Lib\\site-packages\\certifi\\cacert.pem'
2025-05-19 23:43:58,164 - httpx - DEBUG - load_ssl_context verify=True cert=None trust_env=True http2=False
2025-05-19 23:43:58,164 - httpx - DEBUG - load_verify_locations cafile='C:\\Users\\CensoredBear.Natalia\\AppData\\Local\\Programs\\Python\\Python311\\Lib\\site-packages\\certifi\\cacert.pem'
2025-05-19 23:43:58,578 - __main__ - INFO - Application built successfully
2025-05-19 23:43:58,578 - __main__ - INFO - Error handler added
2025-05-19 23:43:58,578 - __main__ - INFO - Go command handler added
2025-05-19 23:43:58,578 - __main__ - INFO - Conversation handler added successfully
2025-05-19 23:43:58,578 - __main__ - INFO - Echo handler added
2025-05-19 23:43:58,578 - telegram.ext.ExtBot - DEBUG - Entering: get_me
2025-05-19 23:43:58,594 - httpcore.connection - DEBUG - connect_tcp.started host='api.telegram.org' port=443 local_address=None timeout=5.0 socket_options=None
2025-05-19 23:43:58,828 - httpcore.connection - DEBUG - connect_tcp.complete return_value=<httpcore._backends.anyio.AnyIOStream object at 0x0000012156D57850>
2025-05-19 23:43:58,836 - httpcore.connection - DEBUG - start_tls.started ssl_context=<ssl.SSLContext object at 0x0000012156C63530> server_hostname='api.telegram.org' timeout=5.0
2025-05-19 23:43:59,065 - httpcore.connection - DEBUG - start_tls.complete return_value=<httpcore._backends.anyio.AnyIOStream object at 0x0000012156D575D0>
2025-05-19 23:43:59,065 - httpcore.http11 - DEBUG - send_request_headers.started request=<Request [b'POST']>
2025-05-19 23:43:59,065 - httpcore.http11 - DEBUG - send_request_headers.complete
2025-05-19 23:43:59,065 - httpcore.http11 - DEBUG - send_request_body.started request=<Request [b'POST']>
2025-05-19 23:43:59,065 - httpcore.http11 - DEBUG - send_request_body.complete
2025-05-19 23:43:59,065 - httpcore.http11 - DEBUG - receive_response_headers.started request=<Request [b'POST']>
2025-05-19 23:43:59,272 - httpcore.http11 - DEBUG - receive_response_headers.complete return_value=(b'HTTP/1.1', 200, b'OK', [(b'Server', b'nginx/1.18.0'), (b'Date', b'Mon, 19 May 2025 15:43:59 GMT'), (b'Content-Type', b'application/json'), (b'Content-Length', b'360'), (b'Connection', b'keep-alive'), (b'Strict-Transport-Security', b'max-age=31536000; includeSubDomains; preload'), (b'Access-Control-Allow-Origin', b'*'), (b'Access-Control-Allow-Methods', b'GET, POST, OPTIONS'), (b'Access-Control-Expose-Headers', b'Content-Length,Content-Type,Date,Server,Connection')])
2025-05-19 23:43:59,272 - httpx - INFO - HTTP Request: POST https://api.telegram.org/bot8190481931:AAHGGuo1Kw6_KQob4xzr6CSOjVl4V58R860/getMe "HTTP/1.1 200 OK"
2025-05-19 23:43:59,272 - httpcore.http11 - DEBUG - receive_response_body.started request=<Request [b'POST']>
2025-05-19 23:43:59,272 - httpcore.http11 - DEBUG - receive_response_body.complete
2025-05-19 23:43:59,272 - httpcore.http11 - DEBUG - response_closed.started
2025-05-19 23:43:59,272 - httpcore.http11 - DEBUG - response_closed.complete
2025-05-19 23:43:59,328 - telegram.ext.ExtBot - DEBUG - Exiting: get_me
2025-05-19 23:43:59,328 - telegram.ext.ExtBot - DEBUG - This Bot is already initialized.
2025-05-19 23:43:59,328 - __main__ - INFO - Application initialized
2025-05-19 23:43:59,328 - telegram.ext.Application - INFO - Application started
2025-05-19 23:43:59,328 - __main__ - INFO - Application started
2025-05-19 23:43:59,328 - telegram.ext.ExtBot - DEBUG - Entering: send_message
2025-05-19 23:43:59,336 - httpcore.http11 - DEBUG - send_request_headers.started request=<Request [b'POST']>
2025-05-19 23:43:59,336 - httpcore.http11 - DEBUG - send_request_headers.complete
2025-05-19 23:43:59,338 - httpcore.http11 - DEBUG - send_request_body.started request=<Request [b'POST']>
2025-05-19 23:43:59,340 - httpcore.http11 - DEBUG - send_request_body.complete
2025-05-19 23:43:59,340 - httpcore.http11 - DEBUG - receive_response_headers.started request=<Request [b'POST']>
2025-05-19 23:43:59,702 - httpcore.http11 - DEBUG - receive_response_headers.complete return_value=(b'HTTP/1.1', 200, b'OK', [(b'Server', b'nginx/1.18.0'), (b'Date', b'Mon, 19 May 2025 15:44:00 GMT'), (b'Content-Type', b'application/json'), (b'Content-Length', b'535'), (b'Connection', b'keep-alive'), (b'Strict-Transport-Security', b'max-age=31536000; includeSubDomains; preload'), (b'Access-Control-Allow-Origin', b'*'), (b'Access-Control-Allow-Methods', b'GET, POST, OPTIONS'), (b'Access-Control-Expose-Headers', b'Content-Length,Content-Type,Date,Server,Connection')])
2025-05-19 23:43:59,702 - httpx - INFO - HTTP Request: POST https://api.telegram.org/bot8190481931:AAHGGuo1Kw6_KQob4xzr6CSOjVl4V58R860/sendMessage "HTTP/1.1 200 OK"
2025-05-19 23:43:59,702 - httpcore.http11 - DEBUG - receive_response_body.started request=<Request [b'POST']>
2025-05-19 23:43:59,702 - httpcore.http11 - DEBUG - receive_response_body.complete
2025-05-19 23:43:59,709 - httpcore.http11 - DEBUG - response_closed.started
2025-05-19 23:43:59,710 - httpcore.http11 - DEBUG - response_closed.complete
2025-05-19 23:43:59,729 - telegram.ext.ExtBot - DEBUG - Exiting: send_message
2025-05-19 23:43:59,729 - __main__ - INFO - Startup message sent to admin
2025-05-19 23:43:59,730 - __main__ - INFO - Starting polling...
2025-05-19 23:43:59,784 - __main__ - ERROR - Error during bot startup: Cannot close a running event loop
2025-05-19 23:43:59,785 - telegram.ext.Application - WARNING - Fetching updates got a asyncio.CancelledError. Ignoring as this task may onlybe closed via `Application.stop`.
2025-05-19 23:45:20,659 - asyncio - DEBUG - Using proactor: IocpProactor
2025-05-19 23:45:20,659 - __main__ - INFO - Starting bot...
2025-05-19 23:45:20,659 - __main__ - INFO - Bot token found: 81904...
2025-05-19 23:45:20,659 - httpx - DEBUG - load_ssl_context verify=True cert=None trust_env=True http2=False
2025-05-19 23:45:20,659 - httpx - DEBUG - load_verify_locations cafile='C:\\Users\\CensoredBear.Natalia\\AppData\\Local\\Programs\\Python\\Python311\\Lib\\site-packages\\certifi\\cacert.pem'
2025-05-19 23:45:21,182 - httpx - DEBUG - load_ssl_context verify=True cert=None trust_env=True http2=False
2025-05-19 23:45:21,182 - httpx - DEBUG - load_verify_locations cafile='C:\\Users\\CensoredBear.Natalia\\AppData\\Local\\Programs\\Python\\Python311\\Lib\\site-packages\\certifi\\cacert.pem'
2025-05-19 23:45:21,578 - __main__ - INFO - Application built successfully
2025-05-19 23:45:21,578 - __main__ - INFO - Error handler added
2025-05-19 23:45:21,578 - __main__ - INFO - Go command handler added
2025-05-19 23:45:21,578 - __main__ - INFO - Conversation handler added successfully
2025-05-19 23:45:21,578 - __main__ - INFO - Echo handler added
2025-05-19 23:45:21,578 - telegram.ext.ExtBot - DEBUG - Entering: get_me
2025-05-19 23:45:21,593 - httpcore.connection - DEBUG - connect_tcp.started host='api.telegram.org' port=443 local_address=None timeout=5.0 socket_options=None
2025-05-19 23:45:21,807 - httpcore.connection - DEBUG - connect_tcp.complete return_value=<httpcore._backends.anyio.AnyIOStream object at 0x000001D5BD21B710>
2025-05-19 23:45:21,810 - httpcore.connection - DEBUG - start_tls.started ssl_context=<ssl.SSLContext object at 0x000001D5BD127530> server_hostname='api.telegram.org' timeout=5.0
2025-05-19 23:45:22,056 - httpcore.connection - DEBUG - start_tls.complete return_value=<httpcore._backends.anyio.AnyIOStream object at 0x000001D5BD21B4D0>
2025-05-19 23:45:22,056 - httpcore.http11 - DEBUG - send_request_headers.started request=<Request [b'POST']>
2025-05-19 23:45:22,056 - httpcore.http11 - DEBUG - send_request_headers.complete
2025-05-19 23:45:22,056 - httpcore.http11 - DEBUG - send_request_body.started request=<Request [b'POST']>
2025-05-19 23:45:22,056 - httpcore.http11 - DEBUG - send_request_body.complete
2025-05-19 23:45:22,056 - httpcore.http11 - DEBUG - receive_response_headers.started request=<Request [b'POST']>
2025-05-19 23:45:22,256 - httpcore.http11 - DEBUG - receive_response_headers.complete return_value=(b'HTTP/1.1', 200, b'OK', [(b'Server', b'nginx/1.18.0'), (b'Date', b'Mon, 19 May 2025 15:45:22 GMT'), (b'Content-Type', b'application/json'), (b'Content-Length', b'360'), (b'Connection', b'keep-alive'), (b'Strict-Transport-Security', b'max-age=31536000; includeSubDomains; preload'), (b'Access-Control-Allow-Origin', b'*'), (b'Access-Control-Allow-Methods', b'GET, POST, OPTIONS'), (b'Access-Control-Expose-Headers', b'Content-Length,Content-Type,Date,Server,Connection')])
2025-05-19 23:45:22,256 - httpx - INFO - HTTP Request: POST https://api.telegram.org/bot8190481931:AAHGGuo1Kw6_KQob4xzr6CSOjVl4V58R860/getMe "HTTP/1.1 200 OK"
2025-05-19 23:45:22,256 - httpcore.http11 - DEBUG - receive_response_body.started request=<Request [b'POST']>
2025-05-19 23:45:22,256 - httpcore.http11 - DEBUG - receive_response_body.complete
2025-05-19 23:45:22,256 - httpcore.http11 - DEBUG - response_closed.started
2025-05-19 23:45:22,256 - httpcore.http11 - DEBUG - response_closed.complete
2025-05-19 23:45:22,290 - telegram.ext.ExtBot - DEBUG - Exiting: get_me
2025-05-19 23:45:22,290 - telegram.ext.ExtBot - DEBUG - This Bot is already initialized.
2025-05-19 23:45:22,295 - __main__ - INFO - Application initialized
2025-05-19 23:45:22,295 - telegram.ext.Application - INFO - Application started
2025-05-19 23:45:22,296 - __main__ - INFO - Application started
2025-05-19 23:45:22,296 - telegram.ext.ExtBot - DEBUG - Entering: send_message
2025-05-19 23:45:22,296 - httpcore.http11 - DEBUG - send_request_headers.started request=<Request [b'POST']>
2025-05-19 23:45:22,296 - httpcore.http11 - DEBUG - send_request_headers.complete
2025-05-19 23:45:22,296 - httpcore.http11 - DEBUG - send_request_body.started request=<Request [b'POST']>
2025-05-19 23:45:22,296 - httpcore.http11 - DEBUG - send_request_body.complete
2025-05-19 23:45:22,303 - httpcore.http11 - DEBUG - receive_response_headers.started request=<Request [b'POST']>
2025-05-19 23:45:22,567 - httpcore.http11 - DEBUG - receive_response_headers.complete return_value=(b'HTTP/1.1', 200, b'OK', [(b'Server', b'nginx/1.18.0'), (b'Date', b'Mon, 19 May 2025 15:45:23 GMT'), (b'Content-Type', b'application/json'), (b'Content-Length', b'535'), (b'Connection', b'keep-alive'), (b'Strict-Transport-Security', b'max-age=31536000; includeSubDomains; preload'), (b'Access-Control-Allow-Origin', b'*'), (b'Access-Control-Allow-Methods', b'GET, POST, OPTIONS'), (b'Access-Control-Expose-Headers', b'Content-Length,Content-Type,Date,Server,Connection')])
2025-05-19 23:45:22,567 - httpx - INFO - HTTP Request: POST https://api.telegram.org/bot8190481931:AAHGGuo1Kw6_KQob4xzr6CSOjVl4V58R860/sendMessage "HTTP/1.1 200 OK"
2025-05-19 23:45:22,567 - httpcore.http11 - DEBUG - receive_response_body.started request=<Request [b'POST']>
2025-05-19 23:45:22,567 - httpcore.http11 - DEBUG - receive_response_body.complete
2025-05-19 23:45:22,567 - httpcore.http11 - DEBUG - response_closed.started
2025-05-19 23:45:22,567 - httpcore.http11 - DEBUG - response_closed.complete
2025-05-19 23:45:22,596 - telegram.ext.ExtBot - DEBUG - Exiting: send_message
2025-05-19 23:45:22,597 - __main__ - INFO - Startup message sent to admin
2025-05-19 23:45:22,597 - __main__ - INFO - Starting polling...
2025-05-19 23:45:22,652 - __main__ - ERROR - Critical error during bot startup: This event loop is already running
Traceback (most recent call last):
  File "C:\Users\CensoredBear.Natalia\AppData\Local\Programs\Python\Python311\Lib\site-packages\telegram\ext\_application.py", line 1006, in __run
    raise exc
  File "C:\Users\CensoredBear.Natalia\AppData\Local\Programs\Python\Python311\Lib\site-packages\telegram\ext\_application.py", line 995, in __run
    loop.run_until_complete(self.initialize())
  File "C:\Users\CensoredBear.Natalia\AppData\Local\Programs\Python\Python311\Lib\asyncio\base_events.py", line 629, in run_until_complete
    self._check_running()
  File "C:\Users\CensoredBear.Natalia\AppData\Local\Programs\Python\Python311\Lib\asyncio\base_events.py", line 588, in _check_running
    raise RuntimeError('This event loop is already running')
RuntimeError: This event loop is already running

During handling of the above exception, another exception occurred:

Traceback (most recent call last):
  File "C:\Users\CensoredBear.Natalia\habit_tracker_bot\bot.py", line 310, in main
    await application.run_polling(
          ^^^^^^^^^^^^^^^^^^^^^^^^
  File "C:\Users\CensoredBear.Natalia\AppData\Local\Programs\Python\Python311\Lib\site-packages\telegram\ext\_application.py", line 818, in run_polling
    return self.__run(
           ^^^^^^^^^^^
  File "C:\Users\CensoredBear.Natalia\AppData\Local\Programs\Python\Python311\Lib\site-packages\telegram\ext\_application.py", line 1014, in __run
    loop.run_until_complete(self.stop())
  File "C:\Users\CensoredBear.Natalia\AppData\Local\Programs\Python\Python311\Lib\asyncio\base_events.py", line 629, in run_until_complete
    self._check_running()
  File "C:\Users\CensoredBear.Natalia\AppData\Local\Programs\Python\Python311\Lib\asyncio\base_events.py", line 588, in _check_running
    raise RuntimeError('This event loop is already running')
RuntimeError: This event loop is already running
2025-05-19 23:45:22,661 - telegram.ext.Application - INFO - Application is stopping. This might take a moment.
2025-05-19 23:45:22,661 - telegram.ext.Application - DEBUG - Waiting for update_queue to join
2025-05-19 23:45:22,662 - telegram.ext.Application - DEBUG - Dropping pending updates
2025-05-19 23:45:22,662 - telegram.ext.Application - DEBUG - Application stopped fetching of updates.
2025-05-19 23:45:22,662 - telegram.ext.Application - DEBUG - Waiting for `create_task` calls to be processed
2025-05-19 23:45:22,663 - telegram.ext.Application - INFO - Application.stop() complete
2025-05-19 23:45:22,663 - httpcore.connection - DEBUG - close.started
2025-05-19 23:45:22,664 - httpcore.connection - DEBUG - close.complete
2025-05-19 23:45:22,665 - telegram.ext.ExtBot - DEBUG - This Bot is already shut down. Returning.
2025-05-19 23:45:22,665 - telegram.ext.Updater - DEBUG - Shut down of Updater complete
2025-05-19 23:45:22,666 - __main__ - INFO - Bot shutdown completed
2025-05-19 23:45:22,666 - __main__ - ERROR - Fatal error occurred: This event loop is already running
Traceback (most recent call last):
  File "C:\Users\CensoredBear.Natalia\AppData\Local\Programs\Python\Python311\Lib\site-packages\telegram\ext\_application.py", line 1006, in __run
    raise exc
  File "C:\Users\CensoredBear.Natalia\AppData\Local\Programs\Python\Python311\Lib\site-packages\telegram\ext\_application.py", line 995, in __run
    loop.run_until_complete(self.initialize())
  File "C:\Users\CensoredBear.Natalia\AppData\Local\Programs\Python\Python311\Lib\asyncio\base_events.py", line 629, in run_until_complete
    self._check_running()
  File "C:\Users\CensoredBear.Natalia\AppData\Local\Programs\Python\Python311\Lib\asyncio\base_events.py", line 588, in _check_running
    raise RuntimeError('This event loop is already running')
RuntimeError: This event loop is already running

During handling of the above exception, another exception occurred:

Traceback (most recent call last):
  File "C:\Users\CensoredBear.Natalia\habit_tracker_bot\bot.py", line 335, in <module>
    loop.run_until_complete(main())
  File "C:\Users\CensoredBear.Natalia\AppData\Local\Programs\Python\Python311\Lib\asyncio\base_events.py", line 653, in run_until_complete
    return future.result()
           ^^^^^^^^^^^^^^^
  File "C:\Users\CensoredBear.Natalia\habit_tracker_bot\bot.py", line 310, in main
    await application.run_polling(
          ^^^^^^^^^^^^^^^^^^^^^^^^
  File "C:\Users\CensoredBear.Natalia\AppData\Local\Programs\Python\Python311\Lib\site-packages\telegram\ext\_application.py", line 818, in run_polling
    return self.__run(
           ^^^^^^^^^^^
  File "C:\Users\CensoredBear.Natalia\AppData\Local\Programs\Python\Python311\Lib\site-packages\telegram\ext\_application.py", line 1014, in __run
    loop.run_until_complete(self.stop())
  File "C:\Users\CensoredBear.Natalia\AppData\Local\Programs\Python\Python311\Lib\asyncio\base_events.py", line 629, in run_until_complete
    self._check_running()
  File "C:\Users\CensoredBear.Natalia\AppData\Local\Programs\Python\Python311\Lib\asyncio\base_events.py", line 588, in _check_running
    raise RuntimeError('This event loop is already running')
RuntimeError: This event loop is already running
